Workbook

Sheet Characters
A1: name | B1: nickname | C1: nation | D1: posteNaturel (12) | E1: role (FM) | F1: posteSecondaire1 | G1: posteSecondaire2 | H1: archetypes (libre, virgules) | I1: style | J1: base OVR (1-93) | K1: pied | L1: taille (cm) | M1: poids (kg) | N1: signature (oui/non) | O1: lora (ref ComfyUI) | P1: bio / lore | Q1: id (AUTO) | R1: photo (AUTO) | S1: refPrefix (AUTO)
A2: Soledad Diaz | B2: Sol | C2: argentine | D2: ST | E2: second_striker | F2: CAM | G2: LW | H2: phenomene,creatif,vision | I2: vista | J2: 93 | K2: both | L2: 174 | M2: 68 | N2: oui | O2: soledad_diaz_v1 | P2: Capitaine de l Albiceleste. Pivot de reference. | Q2: =SUBSTITUTE(SUBSTITUTE(SUBSTITUTE(SUBSTITUTE(SUBSTITUTE(SUBSTITUTE(SUBSTITUTE(SUBSTITUTE(SUBSTITUTE(SUBSTITUTE(SUBSTITUTE(SUBSTITUTE(SUBSTITUTE(SUBSTITUTE(SUBSTITUTE(SUBSTITUTE(SUBSTITUTE(SUBSTITUTE(SUBSTITUTE(SUBSTITUTE(SUBSTITUTE(SUBSTITUTE(SUBSTITUTE(SUBSTITUTE(SUBSTITUTE(SUBSTITUTE(SUBSTITUTE(LOWER(TRIM(A2)),"á","a"),"à","a"),"â","a"),"ä","a"),"ã","a"),"é","e"),"è","e"),"ê","e"),"ë","e"),"í","i"),"ì","i"),"î","i"),"ï","i"),"ó","o"),"ò","o"),"ô","o"),"ö","o"),"õ","o"),"ú","u"),"ù","u"),"û","u"),"ü","u"),"ñ","n"),"ç","c")," ","-"),"'",""),".","") | R2: =IF(A2<>"","cards/football/"&C2/"&Q2/standard.png","") | S2: =IF(C2<>"",VLOOKUP(C2,Références!$A$2:$B$9,2,FALSE),"")
Q3: =SUBSTITUTE(SUBSTITUTE(SUBSTITUTE(SUBSTITUTE(SUBSTITUTE(SUBSTITUTE(SUBSTITUTE(SUBSTITUTE(SUBSTITUTE(SUBSTITUTE(SUBSTITUTE(SUBSTITUTE(SUBSTITUTE(SUBSTITUTE(SUBSTITUTE(SUBSTITUTE(SUBSTITUTE(SUBSTITUTE(SUBSTITUTE(SUBSTITUTE(SUBSTITUTE(SUBSTITUTE(SUBSTITUTE(SUBSTITUTE(SUBSTITUTE(SUBSTITUTE(SUBSTITUTE(LOWER(TRIM(A3)),"á","a"),"à","a"),"â","a"),"ä","a"),"ã","a"),"é","e"),"è","e"),"ê","e"),"ë","e"),"í","i"),"ì","i"),"î","i"),"ï","i"),"ó","o"),"ò","o"),"ô","o"),"ö","o"),"õ","o"),"ú","u"),"ù","u"),"û","u"),"ü","u"),"ñ","n"),"ç","c")," ","-"),"'",""),".","") | R3: =IF(A3<>"","cards/football/"&C3/"&Q3/standard.png","") | S3: =IF(C3<>"",VLOOKUP(C3,Références!$A$2:$B$9,2,FALSE),"")
Q4: =SUBSTITUTE(SUBSTITUTE(SUBSTITUTE(SUBSTITUTE(SUBSTITUTE(SUBSTITUTE(SUBSTITUTE(SUBSTITUTE(SUBSTITUTE(SUBSTITUTE(SUBSTITUTE(SUBSTITUTE(SUBSTITUTE(SUBSTITUTE(SUBSTITUTE(SUBSTITUTE(SUBSTITUTE(SUBSTITUTE(SUBSTITUTE(SUBSTITUTE(SUBSTITUTE(SUBSTITUTE(SUBSTITUTE(SUBSTITUTE(SUBSTITUTE(SUBSTITUTE(SUBSTITUTE(LOWER(TRIM(A4)),"á","a"),"à","a"),"â","a"),"ä","a"),"ã","a"),"é","e"),"è","e"),"ê","e"),"ë","e"),"í","i"),"ì","i"),"î","i"),"ï","i"),"ó","o"),"ò","o"),"ô","o"),"ö","o"),"õ","o"),"ú","u"),"ù","u"),"û","u"),"ü","u"),"ñ","n"),"ç","c")," ","-"),"'",""),".","") | R4: =IF(A4<>"","cards/football/"&C4/"&Q4/standard.png","") | S4: =IF(C4<>"",VLOOKUP(C4,Références!$A$2:$B$9,2,FALSE),"")
Q5: =SUBSTITUTE(SUBSTITUTE(SUBSTITUTE(SUBSTITUTE(SUBSTITUTE(SUBSTITUTE(SUBSTITUTE(SUBSTITUTE(SUBSTITUTE(SUBSTITUTE(SUBSTITUTE(SUBSTITUTE(SUBSTITUTE(SUBSTITUTE(SUBSTITUTE(SUBSTITUTE(SUBSTITUTE(SUBSTITUTE(SUBSTITUTE(SUBSTITUTE(SUBSTITUTE(SUBSTITUTE(SUBSTITUTE(SUBSTITUTE(SUBSTITUTE(SUBSTITUTE(SUBSTITUTE(LOWER(TRIM(A5)),"á","a"),"à","a"),"â","a"),"ä","a"),"ã","a"),"é","e"),"è","e"),"ê","e"),"ë","e"),"í","i"),"ì","i"),"î","i"),"ï","i"),"ó","o"),"ò","o"),"ô","o"),"ö","o"),"õ","o"),"ú","u"),"ù","u"),"û","u"),"ü","u"),"ñ","n"),"ç","c")," ","-"),"'",""),".","") | R5: =IF(A5<>"","cards/football/"&C5/"&Q5/standard.png","") | S5: =IF(C5<>"",VLOOKUP(C5,Références!$A$2:$B$9,2,FALSE),"")
Q6: =SUBSTITUTE(SUBSTITUTE(SUBSTITUTE(SUBSTITUTE(SUBSTITUTE(SUBSTITUTE(SUBSTITUTE(SUBSTITUTE(SUBSTITUTE(SUBSTITUTE(SUBSTITUTE(SUBSTITUTE(SUBSTITUTE(SUBSTITUTE(SUBSTITUTE(SUBSTITUTE(SUBSTITUTE(SUBSTITUTE(SUBSTITUTE(SUBSTITUTE(SUBSTITUTE(SUBSTITUTE(SUBSTITUTE(SUBSTITUTE(SUBSTITUTE(SUBSTITUTE(SUBSTITUTE(LOWER(TRIM(A6)),"á","a"),"à","a"),"â","a"),"ä","a"),"ã","a"),"é","e"),"è","e"),"ê","e"),"ë","e"),"í","i"),"ì","i"),"î","i"),"ï","i"),"ó","o"),"ò","o"),"ô","o"),"ö","o"),"õ","o"),"ú","u"),"ù","u"),"û","u"),"ü","u"),"ñ","n"),"ç","c")," ","-"),"'",""),".","") | R6: =IF(A6<>"","cards/football/"&C6/"&Q6/standard.png","") | S6: =IF(C6<>"",VLOOKUP(C6,Références!$A$2:$B$9,2,FALSE),"")
Q7: =SUBSTITUTE(SUBSTITUTE(SUBSTITUTE(SUBSTITUTE(SUBSTITUTE(SUBSTITUTE(SUBSTITUTE(SUBSTITUTE(SUBSTITUTE(SUBSTITUTE(SUBSTITUTE(SUBSTITUTE(SUBSTITUTE(SUBSTITUTE(SUBSTITUTE(SUBSTITUTE(SUBSTITUTE(SUBSTITUTE(SUBSTITUTE(SUBSTITUTE(SUBSTITUTE(SUBSTITUTE(SUBSTITUTE(SUBSTITUTE(SUBSTITUTE(SUBSTITUTE(SUBSTITUTE(LOWER(TRIM(A7)),"á","a"),"à","a"),"â","a"),"ä","a"),"ã","a"),"é","e"),"è","e"),"ê","e"),"ë","e"),"í","i"),"ì","i"),"î","i"),"ï","i"),"ó","o"),"ò","o"),"ô","o"),"ö","o"),"õ","o"),"ú","u"),"ù","u"),"û","u"),"ü","u"),"ñ","n"),"ç","c")," ","-"),"'",""),".","") | R7: =IF(A7<>"","cards/football/"&C7/"&Q7/standard.png","") | S7: =IF(C7<>"",VLOOKUP(C7,Références!$A$2:$B$9,2,FALSE),"")
Q8: =SUBSTITUTE(SUBSTITUTE(SUBSTITUTE(SUBSTITUTE(SUBSTITUTE(SUBSTITUTE(SUBSTITUTE(SUBSTITUTE(SUBSTITUTE(SUBSTITUTE(SUBSTITUTE(SUBSTITUTE(SUBSTITUTE(SUBSTITUTE(SUBSTITUTE(SUBSTITUTE(SUBSTITUTE(SUBSTITUTE(SUBSTITUTE(SUBSTITUTE(SUBSTITUTE(SUBSTITUTE(SUBSTITUTE(SUBSTITUTE(SUBSTITUTE(SUBSTITUTE(SUBSTITUTE(LOWER(TRIM(A8)),"á","a"),"à","a"),"â","a"),"ä","a"),"ã","a"),"é","e"),"è","e"),"ê","e"),"ë","e"),"í","i"),"ì","i"),"î","i"),"ï","i"),"ó","o"),"ò","o"),"ô","o"),"ö","o"),"õ","o"),"ú","u"),"ù","u"),"û","u"),"ü","u"),"ñ","n"),"ç","c")," ","-"),"'",""),".","") | R8: =IF(A8<>"","cards/football/"&C8/"&Q8/standard.png","") | S8: =IF(C8<>"",VLOOKUP(C8,Références!$A$2:$B$9,2,FALSE),"")
Q9: =SUBSTITUTE(SUBSTITUTE(SUBSTITUTE(SUBSTITUTE(SUBSTITUTE(SUBSTITUTE(SUBSTITUTE(SUBSTITUTE(SUBSTITUTE(SUBSTITUTE(SUBSTITUTE(SUBSTITUTE(SUBSTITUTE(SUBSTITUTE(SUBSTITUTE(SUBSTITUTE(SUBSTITUTE(SUBSTITUTE(SUBSTITUTE(SUBSTITUTE(SUBSTITUTE(SUBSTITUTE(SUBSTITUTE(SUBSTITUTE(SUBSTITUTE(SUBSTITUTE(SUBSTITUTE(LOWER(TRIM(A9)),"á","a"),"à","a"),"â","a"),"ä","a"),"ã","a"),"é","e"),"è","e"),"ê","e"),"ë","e"),"í","i"),"ì","i"),"î","i"),"ï","i"),"ó","o"),"ò","o"),"ô","o"),"ö","o"),"õ","o"),"ú","u"),"ù","u"),"û","u"),"ü","u"),"ñ","n"),"ç","c")," ","-"),"'",""),".","") | R9: =IF(A9<>"","cards/football/"&C9/"&Q9/standard.png","") | S9: =IF(C9<>"",VLOOKUP(C9,Références!$A$2:$B$9,2,FALSE),"")
Q10: =SUBSTITUTE(SUBSTITUTE(SUBSTITUTE(SUBSTITUTE(SUBSTITUTE(SUBSTITUTE(SUBSTITUTE(SUBSTITUTE(SUBSTITUTE(SUBSTITUTE(SUBSTITUTE(SUBSTITUTE(SUBSTITUTE(SUBSTITUTE(SUBSTITUTE(SUBSTITUTE(SUBSTITUTE(SUBSTITUTE(SUBSTITUTE(SUBSTITUTE(SUBSTITUTE(SUBSTITUTE(SUBSTITUTE(SUBSTITUTE(SUBSTITUTE(SUBSTITUTE(SUBSTITUTE(LOWER(TRIM(A10)),"á","a"),"à","a"),"â","a"),"ä","a"),"ã","a"),"é","e"),"è","e"),"ê","e"),"ë","e"),"í","i"),"ì","i"),"î","i"),"ï","i"),"ó","o"),"ò","o"),"ô","o"),"ö","o"),"õ","o"),"ú","u"),"ù","u"),"û","u"),"ü","u"),"ñ","n"),"ç","c")," ","-"),"'",""),".","") | R10: =IF(A10<>"","cards/football/"&C10/"&Q10/standard.png","") | S10: =IF(C10<>"",VLOOKUP(C10,Références!$A$2:$B$9,2,FALSE),"")
Q11: =SUBSTITUTE(SUBSTITUTE(SUBSTITUTE(SUBSTITUTE(SUBSTITUTE(SUBSTITUTE(SUBSTITUTE(SUBSTITUTE(SUBSTITUTE(SUBSTITUTE(SUBSTITUTE(SUBSTITUTE(SUBSTITUTE(SUBSTITUTE(SUBSTITUTE(SUBSTITUTE(SUBSTITUTE(SUBSTITUTE(SUBSTITUTE(SUBSTITUTE(SUBSTITUTE(SUBSTITUTE(SUBSTITUTE(SUBSTITUTE(SUBSTITUTE(SUBSTITUTE(SUBSTITUTE(LOWER(TRIM(A11)),"á","a"),"à","a"),"â","a"),"ä","a"),"ã","a"),"é","e"),"è","e"),"ê","e"),"ë","e"),"í","i"),"ì","i"),"î","i"),"ï","i"),"ó","o"),"ò","o"),"ô","o"),"ö","o"),"õ","o"),"ú","u"),"ù","u"),"û","u"),"ü","u"),"ñ","n"),"ç","c")," ","-"),"'",""),".","") | R11: =IF(A11<>"","cards/football/"&C11/"&Q11/standard.png","") | S11: =IF(C11<>"",VLOOKUP(C11,Références!$A$2:$B$9,2,FALSE),"")
Q12: =SUBSTITUTE(SUBSTITUTE(SUBSTITUTE(SUBSTITUTE(SUBSTITUTE(SUBSTITUTE(SUBSTITUTE(SUBSTITUTE(SUBSTITUTE(SUBSTITUTE(SUBSTITUTE(SUBSTITUTE(SUBSTITUTE(SUBSTITUTE(SUBSTITUTE(SUBSTITUTE(SUBSTITUTE(SUBSTITUTE(SUBSTITUTE(SUBSTITUTE(SUBSTITUTE(SUBSTITUTE(SUBSTITUTE(SUBSTITUTE(SUBSTITUTE(SUBSTITUTE(SUBSTITUTE(LOWER(TRIM(A12)),"á","a"),"à","a"),"â","a"),"ä","a"),"ã","a"),"é","e"),"è","e"),"ê","e"),"ë","e"),"í","i"),"ì","i"),"î","i"),"ï","i"),"ó","o"),"ò","o"),"ô","o"),"ö","o"),"õ","o"),"ú","u"),"ù","u"),"û","u"),"ü","u"),"ñ","n"),"ç","c")," ","-"),"'",""),".","") | R12: =IF(A12<>"","cards/football/"&C12/"&Q12/standard.png","") | S12: =IF(C12<>"",VLOOKUP(C12,Références!$A$2:$B$9,2,FALSE),"")
Q13: =SUBSTITUTE(SUBSTITUTE(SUBSTITUTE(SUBSTITUTE(SUBSTITUTE(SUBSTITUTE(SUBSTITUTE(SUBSTITUTE(SUBSTITUTE(SUBSTITUTE(SUBSTITUTE(SUBSTITUTE(SUBSTITUTE(SUBSTITUTE(SUBSTITUTE(SUBSTITUTE(SUBSTITUTE(SUBSTITUTE(SUBSTITUTE(SUBSTITUTE(SUBSTITUTE(SUBSTITUTE(SUBSTITUTE(SUBSTITUTE(SUBSTITUTE(SUBSTITUTE(SUBSTITUTE(LOWER(TRIM(A13)),"á","a"),"à","a"),"â","a"),"ä","a"),"ã","a"),"é","e"),"è","e"),"ê","e"),"ë","e"),"í","i"),"ì","i"),"î","i"),"ï","i"),"ó","o"),"ò","o"),"ô","o"),"ö","o"),"õ","o"),"ú","u"),"ù","u"),"û","u"),"ü","u"),"ñ","n"),"ç","c")," ","-"),"'",""),".","") | R13: =IF(A13<>"","cards/football/"&C13/"&Q13/standard.png","") | S13: =IF(C13<>"",VLOOKUP(C13,Références!$A$2:$B$9,2,FALSE),"")
Q14: =SUBSTITUTE(SUBSTITUTE(SUBSTITUTE(SUBSTITUTE(SUBSTITUTE(SUBSTITUTE(SUBSTITUTE(SUBSTITUTE(SUBSTITUTE(SUBSTITUTE(SUBSTITUTE(SUBSTITUTE(SUBSTITUTE(SUBSTITUTE(SUBSTITUTE(SUBSTITUTE(SUBSTITUTE(SUBSTITUTE(SUBSTITUTE(SUBSTITUTE(SUBSTITUTE(SUBSTITUTE(SUBSTITUTE(SUBSTITUTE(SUBSTITUTE(SUBSTITUTE(SUBSTITUTE(LOWER(TRIM(A14)),"á","a"),"à","a"),"â","a"),"ä","a"),"ã","a"),"é","e"),"è","e"),"ê","e"),"ë","e"),"í","i"),"ì","i"),"î","i"),"ï","i"),"ó","o"),"ò","o"),"ô","o"),"ö","o"),"õ","o"),"ú","u"),"ù","u"),"û","u"),"ü","u"),"ñ","n"),"ç","c")," ","-"),"'",""),".","") | R14: =IF(A14<>"","cards/football/"&C14/"&Q14/standard.png","") | S14: =IF(C14<>"",VLOOKUP(C14,Références!$A$2:$B$9,2,FALSE),"")
Q15: =SUBSTITUTE(SUBSTITUTE(SUBSTITUTE(SUBSTITUTE(SUBSTITUTE(SUBSTITUTE(SUBSTITUTE(SUBSTITUTE(SUBSTITUTE(SUBSTITUTE(SUBSTITUTE(SUBSTITUTE(SUBSTITUTE(SUBSTITUTE(SUBSTITUTE(SUBSTITUTE(SUBSTITUTE(SUBSTITUTE(SUBSTITUTE(SUBSTITUTE(SUBSTITUTE(SUBSTITUTE(SUBSTITUTE(SUBSTITUTE(SUBSTITUTE(SUBSTITUTE(SUBSTITUTE(LOWER(TRIM(A15)),"á","a"),"à","a"),"â","a"),"ä","a"),"ã","a"),"é","e"),"è","e"),"ê","e"),"ë","e"),"í","i"),"ì","i"),"î","i"),"ï","i"),"ó","o"),"ò","o"),"ô","o"),"ö","o"),"õ","o"),"ú","u"),"ù","u"),"û","u"),"ü","u"),"ñ","n"),"ç","c")," ","-"),"'",""),".","") | R15: =IF(A15<>"","cards/football/"&C15/"&Q15/standard.png","") | S15: =IF(C15<>"",VLOOKUP(C15,Références!$A$2:$B$9,2,FALSE),"")
Q16: =SUBSTITUTE(SUBSTITUTE(SUBSTITUTE(SUBSTITUTE(SUBSTITUTE(SUBSTITUTE(SUBSTITUTE(SUBSTITUTE(SUBSTITUTE(SUBSTITUTE(SUBSTITUTE(SUBSTITUTE(SUBSTITUTE(SUBSTITUTE(SUBSTITUTE(SUBSTITUTE(SUBSTITUTE(SUBSTITUTE(SUBSTITUTE(SUBSTITUTE(SUBSTITUTE(SUBSTITUTE(SUBSTITUTE(SUBSTITUTE(SUBSTITUTE(SUBSTITUTE(SUBSTITUTE(LOWER(TRIM(A16)),"á","a"),"à","a"),"â","a"),"ä","a"),"ã","a"),"é","e"),"è","e"),"ê","e"),"ë","e"),"í","i"),"ì","i"),"î","i"),"ï","i"),"ó","o"),"ò","o"),"ô","o"),"ö","o"),"õ","o"),"ú","u"),"ù","u"),"û","u"),"ü","u"),"ñ","n"),"ç","c")," ","-"),"'",""),".","") | R16: =IF(A16<>"","cards/football/"&C16/"&Q16/standard.png","") | S16: =IF(C16<>"",VLOOKUP(C16,Références!$A$2:$B$9,2,FALSE),"")
Q17: =SUBSTITUTE(SUBSTITUTE(SUBSTITUTE(SUBSTITUTE(SUBSTITUTE(SUBSTITUTE(SUBSTITUTE(SUBSTITUTE(SUBSTITUTE(SUBSTITUTE(SUBSTITUTE(SUBSTITUTE(SUBSTITUTE(SUBSTITUTE(SUBSTITUTE(SUBSTITUTE(SUBSTITUTE(SUBSTITUTE(SUBSTITUTE(SUBSTITUTE(SUBSTITUTE(SUBSTITUTE(SUBSTITUTE(SUBSTITUTE(SUBSTITUTE(SUBSTITUTE(SUBSTITUTE(LOWER(TRIM(A17)),"á","a"),"à","a"),"â","a"),"ä","a"),"ã","a"),"é","e"),"è","e"),"ê","e"),"ë","e"),"í","i"),"ì","i"),"î","i"),"ï","i"),"ó","o"),"ò","o"),"ô","o"),"ö","o"),"õ","o"),"ú","u"),"ù","u"),"û","u"),"ü","u"),"ñ","n"),"ç","c")," ","-"),"'",""),".","") | R17: =IF(A17<>"","cards/football/"&C17/"&Q17/standard.png","") | S17: =IF(C17<>"",VLOOKUP(C17,Références!$A$2:$B$9,2,FALSE),"")
Q18: =SUBSTITUTE(SUBSTITUTE(SUBSTITUTE(SUBSTITUTE(SUBSTITUTE(SUBSTITUTE(SUBSTITUTE(SUBSTITUTE(SUBSTITUTE(SUBSTITUTE(SUBSTITUTE(SUBSTITUTE(SUBSTITUTE(SUBSTITUTE(SUBSTITUTE(SUBSTITUTE(SUBSTITUTE(SUBSTITUTE(SUBSTITUTE(SUBSTITUTE(SUBSTITUTE(SUBSTITUTE(SUBSTITUTE(SUBSTITUTE(SUBSTITUTE(SUBSTITUTE(SUBSTITUTE(LOWER(TRIM(A18)),"á","a"),"à","a"),"â","a"),"ä","a"),"ã","a"),"é","e"),"è","e"),"ê","e"),"ë","e"),"í","i"),"ì","i"),"î","i"),"ï","i"),"ó","o"),"ò","o"),"ô","o"),"ö","o"),"õ","o"),"ú","u"),"ù","u"),"û","u"),"ü","u"),"ñ","n"),"ç","c")," ","-"),"'",""),".","") | R18: =IF(A18<>"","cards/football/"&C18/"&Q18/standard.png","") | S18: =IF(C18<>"",VLOOKUP(C18,Références!$A$2:$B$9,2,FALSE),"")
Q19: =SUBSTITUTE(SUBSTITUTE(SUBSTITUTE(SUBSTITUTE(SUBSTITUTE(SUBSTITUTE(SUBSTITUTE(SUBSTITUTE(SUBSTITUTE(SUBSTITUTE(SUBSTITUTE(SUBSTITUTE(SUBSTITUTE(SUBSTITUTE(SUBSTITUTE(SUBSTITUTE(SUBSTITUTE(SUBSTITUTE(SUBSTITUTE(SUBSTITUTE(SUBSTITUTE(SUBSTITUTE(SUBSTITUTE(SUBSTITUTE(SUBSTITUTE(SUBSTITUTE(SUBSTITUTE(LOWER(TRIM(A19)),"á","a"),"à","a"),"â","a"),"ä","a"),"ã","a"),"é","e"),"è","e"),"ê","e"),"ë","e"),"í","i"),"ì","i"),"î","i"),"ï","i"),"ó","o"),"ò","o"),"ô","o"),"ö","o"),"õ","o"),"ú","u"),"ù","u"),"û","u"),"ü","u"),"ñ","n"),"ç","c")," ","-"),"'",""),".","") | R19: =IF(A19<>"","cards/football/"&C19/"&Q19/standard.png","") | S19: =IF(C19<>"",VLOOKUP(C19,Références!$A$2:$B$9,2,FALSE),"")
Q20: =SUBSTITUTE(SUBSTITUTE(SUBSTITUTE(SUBSTITUTE(SUBSTITUTE(SUBSTITUTE(SUBSTITUTE(SUBSTITUTE(SUBSTITUTE(SUBSTITUTE(SUBSTITUTE(SUBSTITUTE(SUBSTITUTE(SUBSTITUTE(SUBSTITUTE(SUBSTITUTE(SUBSTITUTE(SUBSTITUTE(SUBSTITUTE(SUBSTITUTE(SUBSTITUTE(SUBSTITUTE(SUBSTITUTE(SUBSTITUTE(SUBSTITUTE(SUBSTITUTE(SUBSTITUTE(LOWER(TRIM(A20)),"á","a"),"à","a"),"â","a"),"ä","a"),"ã","a"),"é","e"),"è","e"),"ê","e"),"ë","e"),"í","i"),"ì","i"),"î","i"),"ï","i"),"ó","o"),"ò","o"),"ô","o"),"ö","o"),"õ","o"),"ú","u"),"ù","u"),"û","u"),"ü","u"),"ñ","n"),"ç","c")," ","-"),"'",""),".","") | R20: =IF(A20<>"","cards/football/"&C20/"&Q20/standard.png","") | S20: =IF(C20<>"",VLOOKUP(C20,Références!$A$2:$B$9,2,FALSE),"")
Q21: =SUBSTITUTE(SUBSTITUTE(SUBSTITUTE(SUBSTITUTE(SUBSTITUTE(SUBSTITUTE(SUBSTITUTE(SUBSTITUTE(SUBSTITUTE(SUBSTITUTE(SUBSTITUTE(SUBSTITUTE(SUBSTITUTE(SUBSTITUTE(SUBSTITUTE(SUBSTITUTE(SUBSTITUTE(SUBSTITUTE(SUBSTITUTE(SUBSTITUTE(SUBSTITUTE(SUBSTITUTE(SUBSTITUTE(SUBSTITUTE(SUBSTITUTE(SUBSTITUTE(SUBSTITUTE(LOWER(TRIM(A21)),"á","a"),"à","a"),"â","a"),"ä","a"),"ã","a"),"é","e"),"è","e"),"ê","e"),"ë","e"),"í","i"),"ì","i"),"î","i"),"ï","i"),"ó","o"),"ò","o"),"ô","o"),"ö","o"),"õ","o"),"ú","u"),"ù","u"),"û","u"),"ü","u"),"ñ","n"),"ç","c")," ","-"),"'",""),".","") | R21: =IF(A21<>"","cards/football/"&C21/"&Q21/standard.png","") | S21: =IF(C21<>"",VLOOKUP(C21,Références!$A$2:$B$9,2,FALSE),"")
Q22: =SUBSTITUTE(SUBSTITUTE(SUBSTITUTE(SUBSTITUTE(SUBSTITUTE(SUBSTITUTE(SUBSTITUTE(SUBSTITUTE(SUBSTITUTE(SUBSTITUTE(SUBSTITUTE(SUBSTITUTE(SUBSTITUTE(SUBSTITUTE(SUBSTITUTE(SUBSTITUTE(SUBSTITUTE(SUBSTITUTE(SUBSTITUTE(SUBSTITUTE(SUBSTITUTE(SUBSTITUTE(SUBSTITUTE(SUBSTITUTE(SUBSTITUTE(SUBSTITUTE(SUBSTITUTE(LOWER(TRIM(A22)),"á","a"),"à","a"),"â","a"),"ä","a"),"ã","a"),"é","e"),"è","e"),"ê","e"),"ë","e"),"í","i"),"ì","i"),"î","i"),"ï","i"),"ó","o"),"ò","o"),"ô","o"),"ö","o"),"õ","o"),"ú","u"),"ù","u"),"û","u"),"ü","u"),"ñ","n"),"ç","c")," ","-"),"'",""),".","") | R22: =IF(A22<>"","cards/football/"&C22/"&Q22/standard.png","") | S22: =IF(C22<>"",VLOOKUP(C22,Références!$A$2:$B$9,2,FALSE),"")
Q23: =SUBSTITUTE(SUBSTITUTE(SUBSTITUTE(SUBSTITUTE(SUBSTITUTE(SUBSTITUTE(SUBSTITUTE(SUBSTITUTE(SUBSTITUTE(SUBSTITUTE(SUBSTITUTE(SUBSTITUTE(SUBSTITUTE(SUBSTITUTE(SUBSTITUTE(SUBSTITUTE(SUBSTITUTE(SUBSTITUTE(SUBSTITUTE(SUBSTITUTE(SUBSTITUTE(SUBSTITUTE(SUBSTITUTE(SUBSTITUTE(SUBSTITUTE(SUBSTITUTE(SUBSTITUTE(LOWER(TRIM(A23)),"á","a"),"à","a"),"â","a"),"ä","a"),"ã","a"),"é","e"),"è","e"),"ê","e"),"ë","e"),"í","i"),"ì","i"),"î","i"),"ï","i"),"ó","o"),"ò","o"),"ô","o"),"ö","o"),"õ","o"),"ú","u"),"ù","u"),"û","u"),"ü","u"),"ñ","n"),"ç","c")," ","-"),"'",""),".","") | R23: =IF(A23<>"","cards/football/"&C23/"&Q23/standard.png","") | S23: =IF(C23<>"",VLOOKUP(C23,Références!$A$2:$B$9,2,FALSE),"")
Q24: =SUBSTITUTE(SUBSTITUTE(SUBSTITUTE(SUBSTITUTE(SUBSTITUTE(SUBSTITUTE(SUBSTITUTE(SUBSTITUTE(SUBSTITUTE(SUBSTITUTE(SUBSTITUTE(SUBSTITUTE(SUBSTITUTE(SUBSTITUTE(SUBSTITUTE(SUBSTITUTE(SUBSTITUTE(SUBSTITUTE(SUBSTITUTE(SUBSTITUTE(SUBSTITUTE(SUBSTITUTE(SUBSTITUTE(SUBSTITUTE(SUBSTITUTE(SUBSTITUTE(SUBSTITUTE(LOWER(TRIM(A24)),"á","a"),"à","a"),"â","a"),"ä","a"),"ã","a"),"é","e"),"è","e"),"ê","e"),"ë","e"),"í","i"),"ì","i"),"î","i"),"ï","i"),"ó","o"),"ò","o"),"ô","o"),"ö","o"),"õ","o"),"ú","u"),"ù","u"),"û","u"),"ü","u"),"ñ","n"),"ç","c")," ","-"),"'",""),".","") | R24: =IF(A24<>"","cards/football/"&C24/"&Q24/standard.png","") | S24: =IF(C24<>"",VLOOKUP(C24,Références!$A$2:$B$9,2,FALSE),"")
Q25: =SUBSTITUTE(SUBSTITUTE(SUBSTITUTE(SUBSTITUTE(SUBSTITUTE(SUBSTITUTE(SUBSTITUTE(SUBSTITUTE(SUBSTITUTE(SUBSTITUTE(SUBSTITUTE(SUBSTITUTE(SUBSTITUTE(SUBSTITUTE(SUBSTITUTE(SUBSTITUTE(SUBSTITUTE(SUBSTITUTE(SUBSTITUTE(SUBSTITUTE(SUBSTITUTE(SUBSTITUTE(SUBSTITUTE(SUBSTITUTE(SUBSTITUTE(SUBSTITUTE(SUBSTITUTE(LOWER(TRIM(A25)),"á","a"),"à","a"),"â","a"),"ä","a"),"ã","a"),"é","e"),"è","e"),"ê","e"),"ë","e"),"í","i"),"ì","i"),"î","i"),"ï","i"),"ó","o"),"ò","o"),"ô","o"),"ö","o"),"õ","o"),"ú","u"),"ù","u"),"û","u"),"ü","u"),"ñ","n"),"ç","c")," ","-"),"'",""),".","") | R25: =IF(A25<>"","cards/football/"&C25/"&Q25/standard.png","") | S25: =IF(C25<>"",VLOOKUP(C25,Références!$A$2:$B$9,2,FALSE),"")
Q26: =SUBSTITUTE(SUBSTITUTE(SUBSTITUTE(SUBSTITUTE(SUBSTITUTE(SUBSTITUTE(SUBSTITUTE(SUBSTITUTE(SUBSTITUTE(SUBSTITUTE(SUBSTITUTE(SUBSTITUTE(SUBSTITUTE(SUBSTITUTE(SUBSTITUTE(SUBSTITUTE(SUBSTITUTE(SUBSTITUTE(SUBSTITUTE(SUBSTITUTE(SUBSTITUTE(SUBSTITUTE(SUBSTITUTE(SUBSTITUTE(SUBSTITUTE(SUBSTITUTE(SUBSTITUTE(LOWER(TRIM(A26)),"á","a"),"à","a"),"â","a"),"ä","a"),"ã","a"),"é","e"),"è","e"),"ê","e"),"ë","e"),"í","i"),"ì","i"),"î","i"),"ï","i"),"ó","o"),"ò","o"),"ô","o"),"ö","o"),"õ","o"),"ú","u"),"ù","u"),"û","u"),"ü","u"),"ñ","n"),"ç","c")," ","-"),"'",""),".","") | R26: =IF(A26<>"","cards/football/"&C26/"&Q26/standard.png","") | S26: =IF(C26<>"",VLOOKUP(C26,Références!$A$2:$B$9,2,FALSE),"")
Q27: =SUBSTITUTE(SUBSTITUTE(SUBSTITUTE(SUBSTITUTE(SUBSTITUTE(SUBSTITUTE(SUBSTITUTE(SUBSTITUTE(SUBSTITUTE(SUBSTITUTE(SUBSTITUTE(SUBSTITUTE(SUBSTITUTE(SUBSTITUTE(SUBSTITUTE(SUBSTITUTE(SUBSTITUTE(SUBSTITUTE(SUBSTITUTE(SUBSTITUTE(SUBSTITUTE(SUBSTITUTE(SUBSTITUTE(SUBSTITUTE(SUBSTITUTE(SUBSTITUTE(SUBSTITUTE(LOWER(TRIM(A27)),"á","a"),"à","a"),"â","a"),"ä","a"),"ã","a"),"é","e"),"è","e"),"ê","e"),"ë","e"),"í","i"),"ì","i"),"î","i"),"ï","i"),"ó","o"),"ò","o"),"ô","o"),"ö","o"),"õ","o"),"ú","u"),"ù","u"),"û","u"),"ü","u"),"ñ","n"),"ç","c")," ","-"),"'",""),".","") | R27: =IF(A27<>"","cards/football/"&C27/"&Q27/standard.png","") | S27: =IF(C27<>"",VLOOKUP(C27,Références!$A$2:$B$9,2,FALSE),"")
Q28: =SUBSTITUTE(SUBSTITUTE(SUBSTITUTE(SUBSTITUTE(SUBSTITUTE(SUBSTITUTE(SUBSTITUTE(SUBSTITUTE(SUBSTITUTE(SUBSTITUTE(SUBSTITUTE(SUBSTITUTE(SUBSTITUTE(SUBSTITUTE(SUBSTITUTE(SUBSTITUTE(SUBSTITUTE(SUBSTITUTE(SUBSTITUTE(SUBSTITUTE(SUBSTITUTE(SUBSTITUTE(SUBSTITUTE(SUBSTITUTE(SUBSTITUTE(SUBSTITUTE(SUBSTITUTE(LOWER(TRIM(A28)),"á","a"),"à","a"),"â","a"),"ä","a"),"ã","a"),"é","e"),"è","e"),"ê","e"),"ë","e"),"í","i"),"ì","i"),"î","i"),"ï","i"),"ó","o"),"ò","o"),"ô","o"),"ö","o"),"õ","o"),"ú","u"),"ù","u"),"û","u"),"ü","u"),"ñ","n"),"ç","c")," ","-"),"'",""),".","") | R28: =IF(A28<>"","cards/football/"&C28/"&Q28/standard.png","") | S28: =IF(C28<>"",VLOOKUP(C28,Références!$A$2:$B$9,2,FALSE),"")
Q29: =SUBSTITUTE(SUBSTITUTE(SUBSTITUTE(SUBSTITUTE(SUBSTITUTE(SUBSTITUTE(SUBSTITUTE(SUBSTITUTE(SUBSTITUTE(SUBSTITUTE(SUBSTITUTE(SUBSTITUTE(SUBSTITUTE(SUBSTITUTE(SUBSTITUTE(SUBSTITUTE(SUBSTITUTE(SUBSTITUTE(SUBSTITUTE(SUBSTITUTE(SUBSTITUTE(SUBSTITUTE(SUBSTITUTE(SUBSTITUTE(SUBSTITUTE(SUBSTITUTE(SUBSTITUTE(LOWER(TRIM(A29)),"á","a"),"à","a"),"â","a"),"ä","a"),"ã","a"),"é","e"),"è","e"),"ê","e"),"ë","e"),"í","i"),"ì","i"),"î","i"),"ï","i"),"ó","o"),"ò","o"),"ô","o"),"ö","o"),"õ","o"),"ú","u"),"ù","u"),"û","u"),"ü","u"),"ñ","n"),"ç","c")," ","-"),"'",""),".","") | R29: =IF(A29<>"","cards/football/"&C29/"&Q29/standard.png","") | S29: =IF(C29<>"",VLOOKUP(C29,Références!$A$2:$B$9,2,FALSE),"")
Q30: =SUBSTITUTE(SUBSTITUTE(SUBSTITUTE(SUBSTITUTE(SUBSTITUTE(SUBSTITUTE(SUBSTITUTE(SUBSTITUTE(SUBSTITUTE(SUBSTITUTE(SUBSTITUTE(SUBSTITUTE(SUBSTITUTE(SUBSTITUTE(SUBSTITUTE(SUBSTITUTE(SUBSTITUTE(SUBSTITUTE(SUBSTITUTE(SUBSTITUTE(SUBSTITUTE(SUBSTITUTE(SUBSTITUTE(SUBSTITUTE(SUBSTITUTE(SUBSTITUTE(SUBSTITUTE(LOWER(TRIM(A30)),"á","a"),"à","a"),"â","a"),"ä","a"),"ã","a"),"é","e"),"è","e"),"ê","e"),"ë","e"),"í","i"),"ì","i"),"î","i"),"ï","i"),"ó","o"),"ò","o"),"ô","o"),"ö","o"),"õ","o"),"ú","u"),"ù","u"),"û","u"),"ü","u"),"ñ","n"),"ç","c")," ","-"),"'",""),".","") | R30: =IF(A30<>"","cards/football/"&C30/"&Q30/standard.png","") | S30: =IF(C30<>"",VLOOKUP(C30,Références!$A$2:$B$9,2,FALSE),"")
Q31: =SUBSTITUTE(SUBSTITUTE(SUBSTITUTE(SUBSTITUTE(SUBSTITUTE(SUBSTITUTE(SUBSTITUTE(SUBSTITUTE(SUBSTITUTE(SUBSTITUTE(SUBSTITUTE(SUBSTITUTE(SUBSTITUTE(SUBSTITUTE(SUBSTITUTE(SUBSTITUTE(SUBSTITUTE(SUBSTITUTE(SUBSTITUTE(SUBSTITUTE(SUBSTITUTE(SUBSTITUTE(SUBSTITUTE(SUBSTITUTE(SUBSTITUTE(SUBSTITUTE(SUBSTITUTE(LOWER(TRIM(A31)),"á","a"),"à","a"),"â","a"),"ä","a"),"ã","a"),"é","e"),"è","e"),"ê","e"),"ë","e"),"í","i"),"ì","i"),"î","i"),"ï","i"),"ó","o"),"ò","o"),"ô","o"),"ö","o"),"õ","o"),"ú","u"),"ù","u"),"û","u"),"ü","u"),"ñ","n"),"ç","c")," ","-"),"'",""),".","") | R31: =IF(A31<>"","cards/football/"&C31/"&Q31/standard.png","") | S31: =IF(C31<>"",VLOOKUP(C31,Références!$A$2:$B$9,2,FALSE),"")
Q32: =SUBSTITUTE(SUBSTITUTE(SUBSTITUTE(SUBSTITUTE(SUBSTITUTE(SUBSTITUTE(SUBSTITUTE(SUBSTITUTE(SUBSTITUTE(SUBSTITUTE(SUBSTITUTE(SUBSTITUTE(SUBSTITUTE(SUBSTITUTE(SUBSTITUTE(SUBSTITUTE(SUBSTITUTE(SUBSTITUTE(SUBSTITUTE(SUBSTITUTE(SUBSTITUTE(SUBSTITUTE(SUBSTITUTE(SUBSTITUTE(SUBSTITUTE(SUBSTITUTE(SUBSTITUTE(LOWER(TRIM(A32)),"á","a"),"à","a"),"â","a"),"ä","a"),"ã","a"),"é","e"),"è","e"),"ê","e"),"ë","e"),"í","i"),"ì","i"),"î","i"),"ï","i"),"ó","o"),"ò","o"),"ô","o"),"ö","o"),"õ","o"),"ú","u"),"ù","u"),"û","u"),"ü","u"),"ñ","n"),"ç","c")," ","-"),"'",""),".","") | R32: =IF(A32<>"","cards/football/"&C32/"&Q32/standard.png","") | S32: =IF(C32<>"",VLOOKUP(C32,Références!$A$2:$B$9,2,FALSE),"")
Q33: =SUBSTITUTE(SUBSTITUTE(SUBSTITUTE(SUBSTITUTE(SUBSTITUTE(SUBSTITUTE(SUBSTITUTE(SUBSTITUTE(SUBSTITUTE(SUBSTITUTE(SUBSTITUTE(SUBSTITUTE(SUBSTITUTE(SUBSTITUTE(SUBSTITUTE(SUBSTITUTE(SUBSTITUTE(SUBSTITUTE(SUBSTITUTE(SUBSTITUTE(SUBSTITUTE(SUBSTITUTE(SUBSTITUTE(SUBSTITUTE(SUBSTITUTE(SUBSTITUTE(SUBSTITUTE(LOWER(TRIM(A33)),"á","a"),"à","a"),"â","a"),"ä","a"),"ã","a"),"é","e"),"è","e"),"ê","e"),"ë","e"),"í","i"),"ì","i"),"î","i"),"ï","i"),"ó","o"),"ò","o"),"ô","o"),"ö","o"),"õ","o"),"ú","u"),"ù","u"),"û","u"),"ü","u"),"ñ","n"),"ç","c")," ","-"),"'",""),".","") | R33: =IF(A33<>"","cards/football/"&C33/"&Q33/standard.png","") | S33: =IF(C33<>"",VLOOKUP(C33,Références!$A$2:$B$9,2,FALSE),"")
Q34: =SUBSTITUTE(SUBSTITUTE(SUBSTITUTE(SUBSTITUTE(SUBSTITUTE(SUBSTITUTE(SUBSTITUTE(SUBSTITUTE(SUBSTITUTE(SUBSTITUTE(SUBSTITUTE(SUBSTITUTE(SUBSTITUTE(SUBSTITUTE(SUBSTITUTE(SUBSTITUTE(SUBSTITUTE(SUBSTITUTE(SUBSTITUTE(SUBSTITUTE(SUBSTITUTE(SUBSTITUTE(SUBSTITUTE(SUBSTITUTE(SUBSTITUTE(SUBSTITUTE(SUBSTITUTE(LOWER(TRIM(A34)),"á","a"),"à","a"),"â","a"),"ä","a"),"ã","a"),"é","e"),"è","e"),"ê","e"),"ë","e"),"í","i"),"ì","i"),"î","i"),"ï","i"),"ó","o"),"ò","o"),"ô","o"),"ö","o"),"õ","o"),"ú","u"),"ù","u"),"û","u"),"ü","u"),"ñ","n"),"ç","c")," ","-"),"'",""),".","") | R34: =IF(A34<>"","cards/football/"&C34/"&Q34/standard.png","") | S34: =IF(C34<>"",VLOOKUP(C34,Références!$A$2:$B$9,2,FALSE),"")
Q35: =SUBSTITUTE(SUBSTITUTE(SUBSTITUTE(SUBSTITUTE(SUBSTITUTE(SUBSTITUTE(SUBSTITUTE(SUBSTITUTE(SUBSTITUTE(SUBSTITUTE(SUBSTITUTE(SUBSTITUTE(SUBSTITUTE(SUBSTITUTE(SUBSTITUTE(SUBSTITUTE(SUBSTITUTE(SUBSTITUTE(SUBSTITUTE(SUBSTITUTE(SUBSTITUTE(SUBSTITUTE(SUBSTITUTE(SUBSTITUTE(SUBSTITUTE(SUBSTITUTE(SUBSTITUTE(LOWER(TRIM(A35)),"á","a"),"à","a"),"â","a"),"ä","a"),"ã","a"),"é","e"),"è","e"),"ê","e"),"ë","e"),"í","i"),"ì","i"),"î","i"),"ï","i"),"ó","o"),"ò","o"),"ô","o"),"ö","o"),"õ","o"),"ú","u"),"ù","u"),"û","u"),"ü","u"),"ñ","n"),"ç","c")," ","-"),"'",""),".","") | R35: =IF(A35<>"","cards/football/"&C35/"&Q35/standard.png","") | S35: =IF(C35<>"",VLOOKUP(C35,Références!$A$2:$B$9,2,FALSE),"")
Q36: =SUBSTITUTE(SUBSTITUTE(SUBSTITUTE(SUBSTITUTE(SUBSTITUTE(SUBSTITUTE(SUBSTITUTE(SUBSTITUTE(SUBSTITUTE(SUBSTITUTE(SUBSTITUTE(SUBSTITUTE(SUBSTITUTE(SUBSTITUTE(SUBSTITUTE(SUBSTITUTE(SUBSTITUTE(SUBSTITUTE(SUBSTITUTE(SUBSTITUTE(SUBSTITUTE(SUBSTITUTE(SUBSTITUTE(SUBSTITUTE(SUBSTITUTE(SUBSTITUTE(SUBSTITUTE(LOWER(TRIM(A36)),"á","a"),"à","a"),"â","a"),"ä","a"),"ã","a"),"é","e"),"è","e"),"ê","e"),"ë","e"),"í","i"),"ì","i"),"î","i"),"ï","i"),"ó","o"),"ò","o"),"ô","o"),"ö","o"),"õ","o"),"ú","u"),"ù","u"),"û","u"),"ü","u"),"ñ","n"),"ç","c")," ","-"),"'",""),".","") | R36: =IF(A36<>"","cards/football/"&C36/"&Q36/standard.png","") | S36: =IF(C36<>"",VLOOKUP(C36,Références!$A$2:$B$9,2,FALSE),"")
Q37: =SUBSTITUTE(SUBSTITUTE(SUBSTITUTE(SUBSTITUTE(SUBSTITUTE(SUBSTITUTE(SUBSTITUTE(SUBSTITUTE(SUBSTITUTE(SUBSTITUTE(SUBSTITUTE(SUBSTITUTE(SUBSTITUTE(SUBSTITUTE(SUBSTITUTE(SUBSTITUTE(SUBSTITUTE(SUBSTITUTE(SUBSTITUTE(SUBSTITUTE(SUBSTITUTE(SUBSTITUTE(SUBSTITUTE(SUBSTITUTE(SUBSTITUTE(SUBSTITUTE(SUBSTITUTE(LOWER(TRIM(A37)),"á","a"),"à","a"),"â","a"),"ä","a"),"ã","a"),"é","e"),"è","e"),"ê","e"),"ë","e"),"í","i"),"ì","i"),"î","i"),"ï","i"),"ó","o"),"ò","o"),"ô","o"),"ö","o"),"õ","o"),"ú","u"),"ù","u"),"û","u"),"ü","u"),"ñ","n"),"ç","c")," ","-"),"'",""),".","") | R37: =IF(A37<>"","cards/football/"&C37/"&Q37/standard.png","") | S37: =IF(C37<>"",VLOOKUP(C37,Références!$A$2:$B$9,2,FALSE),"")
Q38: =SUBSTITUTE(SUBSTITUTE(SUBSTITUTE(SUBSTITUTE(SUBSTITUTE(SUBSTITUTE(SUBSTITUTE(SUBSTITUTE(SUBSTITUTE(SUBSTITUTE(SUBSTITUTE(SUBSTITUTE(SUBSTITUTE(SUBSTITUTE(SUBSTITUTE(SUBSTITUTE(SUBSTITUTE(SUBSTITUTE(SUBSTITUTE(SUBSTITUTE(SUBSTITUTE(SUBSTITUTE(SUBSTITUTE(SUBSTITUTE(SUBSTITUTE(SUBSTITUTE(SUBSTITUTE(LOWER(TRIM(A38)),"á","a"),"à","a"),"â","a"),"ä","a"),"ã","a"),"é","e"),"è","e"),"ê","e"),"ë","e"),"í","i"),"ì","i"),"î","i"),"ï","i"),"ó","o"),"ò","o"),"ô","o"),"ö","o"),"õ","o"),"ú","u"),"ù","u"),"û","u"),"ü","u"),"ñ","n"),"ç","c")," ","-"),"'",""),".","") | R38: =IF(A38<>"","cards/football/"&C38/"&Q38/standard.png","") | S38: =IF(C38<>"",VLOOKUP(C38,Références!$A$2:$B$9,2,FALSE),"")
Q39: =SUBSTITUTE(SUBSTITUTE(SUBSTITUTE(SUBSTITUTE(SUBSTITUTE(SUBSTITUTE(SUBSTITUTE(SUBSTITUTE(SUBSTITUTE(SUBSTITUTE(SUBSTITUTE(SUBSTITUTE(SUBSTITUTE(SUBSTITUTE(SUBSTITUTE(SUBSTITUTE(SUBSTITUTE(SUBSTITUTE(SUBSTITUTE(SUBSTITUTE(SUBSTITUTE(SUBSTITUTE(SUBSTITUTE(SUBSTITUTE(SUBSTITUTE(SUBSTITUTE(SUBSTITUTE(LOWER(TRIM(A39)),"á","a"),"à","a"),"â","a"),"ä","a"),"ã","a"),"é","e"),"è","e"),"ê","e"),"ë","e"),"í","i"),"ì","i"),"î","i"),"ï","i"),"ó","o"),"ò","o"),"ô","o"),"ö","o"),"õ","o"),"ú","u"),"ù","u"),"û","u"),"ü","u"),"ñ","n"),"ç","c")," ","-"),"'",""),".","") | R39: =IF(A39<>"","cards/football/"&C39/"&Q39/standard.png","") | S39: =IF(C39<>"",VLOOKUP(C39,Références!$A$2:$B$9,2,FALSE),"")
Q40: =SUBSTITUTE(SUBSTITUTE(SUBSTITUTE(SUBSTITUTE(SUBSTITUTE(SUBSTITUTE(SUBSTITUTE(SUBSTITUTE(SUBSTITUTE(SUBSTITUTE(SUBSTITUTE(SUBSTITUTE(SUBSTITUTE(SUBSTITUTE(SUBSTITUTE(SUBSTITUTE(SUBSTITUTE(SUBSTITUTE(SUBSTITUTE(SUBSTITUTE(SUBSTITUTE(SUBSTITUTE(SUBSTITUTE(SUBSTITUTE(SUBSTITUTE(SUBSTITUTE(SUBSTITUTE(LOWER(TRIM(A40)),"á","a"),"à","a"),"â","a"),"ä","a"),"ã","a"),"é","e"),"è","e"),"ê","e"),"ë","e"),"í","i"),"ì","i"),"î","i"),"ï","i"),"ó","o"),"ò","o"),"ô","o"),"ö","o"),"õ","o"),"ú","u"),"ù","u"),"û","u"),"ü","u"),"ñ","n"),"ç","c")," ","-"),"'",""),".","") | R40: =IF(A40<>"","cards/football/"&C40/"&Q40/standard.png","") | S40: =IF(C40<>"",VLOOKUP(C40,Références!$A$2:$B$9,2,FALSE),"")
...

Sheet Stats & OVR
A1: id (auto) | B1: name (auto) | C1: nation (auto) | D1: poste (auto) | E1: BASE (auto) | F1: Vitesse | G1: Accélération | H1: Endurance | I1: Puissance | J1: Agilité | K1: Détente | L1: Anticipation | M1: SangFroid | N1: Leadership | O1: Positionnement | P1: Agressivité | Q1: Décision | R1: Passe | S1: Tir | T1: Dribble | U1: Centre | V1: Tacle | W1: Technique | X1: CF | Y1: Corners | Z1: Penalty | AA1: LongThrows | AB1: OVR (calc pull) | AC1: Tier (auto) | AD1: — GK BLOCK — | AE1: Vitesse | AF1: Accélération | AG1: Endurance | AH1: Puissance | AI1: Agilité | AJ1: Détente | AK1: Anticipation | AL1: SangFroid | AM1: Leadership | AN1: Positionnement | AO1: Agressivité | AP1: Décision | AQ1: Réflexes | AR1: Handling | AS1: AerialReach | AT1: CommandArea | AU1: Kicking | AV1: RushingOut | AW1: CF | AX1: Corners | AY1: Penalty | AZ1: LongThrows
A2: =Characters!Q2 | B2: =Characters!A2 | C2: =Characters!C2 | D2: =Characters!D2 | E2: =Characters!J2 | AB2: OVR=BASE x frac+jitter au pull | AC2: =IF(E2>=90,"legend",IF(E2>=82,"star",IF(E2>=70,"regular","rookie")))
A3: =Characters!Q3 | B3: =Characters!A3 | C3: =Characters!C3 | D3: =Characters!D3 | E3: =Characters!J3 | AB3: OVR=BASE x frac+jitter au pull | AC3: =IF(E3>=90,"legend",IF(E3>=82,"star",IF(E3>=70,"regular","rookie")))
A4: =Characters!Q4 | B4: =Characters!A4 | C4: =Characters!C4 | D4: =Characters!D4 | E4: =Characters!J4 | AB4: OVR=BASE x frac+jitter au pull | AC4: =IF(E4>=90,"legend",IF(E4>=82,"star",IF(E4>=70,"regular","rookie")))
A5: =Characters!Q5 | B5: =Characters!A5 | C5: =Characters!C5 | D5: =Characters!D5 | E5: =Characters!J5 | AB5: OVR=BASE x frac+jitter au pull | AC5: =IF(E5>=90,"legend",IF(E5>=82,"star",IF(E5>=70,"regular","rookie")))
A6: =Characters!Q6 | B6: =Characters!A6 | C6: =Characters!C6 | D6: =Characters!D6 | E6: =Characters!J6 | AB6: OVR=BASE x frac+jitter au pull | AC6: =IF(E6>=90,"legend",IF(E6>=82,"star",IF(E6>=70,"regular","rookie")))
A7: =Characters!Q7 | B7: =Characters!A7 | C7: =Characters!C7 | D7: =Characters!D7 | E7: =Characters!J7 | AB7: OVR=BASE x frac+jitter au pull | AC7: =IF(E7>=90,"legend",IF(E7>=82,"star",IF(E7>=70,"regular","rookie")))
A8: =Characters!Q8 | B8: =Characters!A8 | C8: =Characters!C8 | D8: =Characters!D8 | E8: =Characters!J8 | AB8: OVR=BASE x frac+jitter au pull | AC8: =IF(E8>=90,"legend",IF(E8>=82,"star",IF(E8>=70,"regular","rookie")))
A9: =Characters!Q9 | B9: =Characters!A9 | C9: =Characters!C9 | D9: =Characters!D9 | E9: =Characters!J9 | AB9: OVR=BASE x frac+jitter au pull | AC9: =IF(E9>=90,"legend",IF(E9>=82,"star",IF(E9>=70,"regular","rookie")))
A10: =Characters!Q10 | B10: =Characters!A10 | C10: =Characters!C10 | D10: =Characters!D10 | E10: =Characters!J10 | AB10: OVR=BASE x frac+jitter au pull | AC10: =IF(E10>=90,"legend",IF(E10>=82,"star",IF(E10>=70,"regular","rookie")))
A11: =Characters!Q11 | B11: =Characters!A11 | C11: =Characters!C11 | D11: =Characters!D11 | E11: =Characters!J11 | AB11: OVR=BASE x frac+jitter au pull | AC11: =IF(E11>=90,"legend",IF(E11>=82,"star",IF(E11>=70,"regular","rookie")))
A12: =Characters!Q12 | B12: =Characters!A12 | C12: =Characters!C12 | D12: =Characters!D12 | E12: =Characters!J12 | AB12: OVR=BASE x frac+jitter au pull | AC12: =IF(E12>=90,"legend",IF(E12>=82,"star",IF(E12>=70,"regular","rookie")))
A13: =Characters!Q13 | B13: =Characters!A13 | C13: =Characters!C13 | D13: =Characters!D13 | E13: =Characters!J13 | AB13: OVR=BASE x frac+jitter au pull | AC13: =IF(E13>=90,"legend",IF(E13>=82,"star",IF(E13>=70,"regular","rookie")))
... A89: =Characters!Q89 | B89: =Characters!A89 | C89: =Characters!C89 | D89: =Characters!D89 | E89: =Characters!J89 | AB89: OVR=BASE x frac+jitter au pull | AC89: =IF(E89>=90,"legend",IF(E89>=82,"star",IF(E89>=70,"regular","rookie")))

Sheet Card Prints
A1: id (auto) | B1: characterId (auto) | C1: editionCode | D1: rarity | E1: refCode (auto) | F1: mintCap (auto) | G1: minted | H1: skillslots (auto)
A2: =LOWER(Characters!$Q2)&"-s1-common" | B2: =Characters!$Q2 | C2: S1 | D2: common | E2: =Characters!$S2-"&Characters!$Q2-"&UPPER(LEFT("common",1)) | F2: =IF(D2="legendary",1000,IF(D2="secret",100,"")) | G2: 0 | H2: =IF(D2="common",0,IF(D2="rare",1,IF(D2="epic",2,IF(D2="legendary",3,4))))
A3: =LOWER(Characters!$Q2)&"-s1-rare" | B3: =Characters!$Q2 | C3: S1 | D3: rare | E3: =Characters!$S2-"&Characters!$Q2-"&UPPER(LEFT("rare",1)) | F3: =IF(D3="legendary",1000,IF(D3="secret",100,"")) | G3: 0 | H3: =IF(D3="common",0,IF(D3="rare",1,IF(D3="epic",2,IF(D3="legendary",3,4))))
A4: =LOWER(Characters!$Q2)&"-s1-epic" | B4: =Characters!$Q2 | C4: S1 | D4: epic | E4: =Characters!$S2-"&Characters!$Q2-"&UPPER(LEFT("epic",1)) | F4: =IF(D4="legendary",1000,IF(D4="secret",100,"")) | G4: 0 | H4: =IF(D4="common",0,IF(D4="rare",1,IF(D4="epic",2,IF(D4="legendary",3,4))))
A5: =LOWER(Characters!$Q2)&"-s1-legendary" | B5: =Characters!$Q2 | C5: S1 | D5: legendary | E5: =Characters!$S2-"&Characters!$Q2-"&UPPER(LEFT("legendary",1)) | F5: =IF(D5="legendary",1000,IF(D5="secret",100,"")) | G5: 0 | H5: =IF(D5="common",0,IF(D5="rare",1,IF(D5="epic",2,IF(D5="legendary",3,4))))
A6: =LOWER(Characters!$Q2)&"-s1-secret" | B6: =Characters!$Q2 | C6: S1 | D6: secret | E6: =Characters!$S2-"&Characters!$Q2-"&UPPER(LEFT("secret",1)) | F6: =IF(D6="legendary",1000,IF(D6="secret",100,"")) | G6: 0 | H6: =IF(D6="common",0,IF(D6="rare",1,IF(D6="epic",2,IF(D6="legendary",3,4))))
A7: =LOWER(Characters!$Q3)&"-s1-common" | B7: =Characters!$Q3 | C7: S1 | D7: common | E7: =Characters!$S3-"&Characters!$Q3-"&UPPER(LEFT("common",1)) | F7: =IF(D7="legendary",1000,IF(D7="secret",100,"")) | G7: 0 | H7: =IF(D7="common",0,IF(D7="rare",1,IF(D7="epic",2,IF(D7="legendary",3,4))))
A8: =LOWER(Characters!$Q3)&"-s1-rare" | B8: =Characters!$Q3 | C8: S1 | D8: rare | E8: =Characters!$S3-"&Characters!$Q3-"&UPPER(LEFT("rare",1)) | F8: =IF(D8="legendary",1000,IF(D8="secret",100,"")) | G8: 0 | H8: =IF(D8="common",0,IF(D8="rare",1,IF(D8="epic",2,IF(D8="legendary",3,4))))
A9: =LOWER(Characters!$Q3)&"-s1-epic" | B9: =Characters!$Q3 | C9: S1 | D9: epic | E9: =Characters!$S3-"&Characters!$Q3-"&UPPER(LEFT("epic",1)) | F9: =IF(D9="legendary",1000,IF(D9="secret",100,"")) | G9: 0 | H9: =IF(D9="common",0,IF(D9="rare",1,IF(D9="epic",2,IF(D9="legendary",3,4))))
A10: =LOWER(Characters!$Q3)&"-s1-legendary" | B10: =Characters!$Q3 | C10: S1 | D10: legendary | E10: =Characters!$S3-"&Characters!$Q3-"&UPPER(LEFT("legendary",1)) | F10: =IF(D10="legendary",1000,IF(D10="secret",100,"")) | G10: 0 | H10: =IF(D10="common",0,IF(D10="rare",1,IF(D10="epic",2,IF(D10="legendary",3,4))))
A11: =LOWER(Characters!$Q3)&"-s1-secret" | B11: =Characters!$Q3 | C11: S1 | D11: secret | E11: =Characters!$S3-"&Characters!$Q3-"&UPPER(LEFT("secret",1)) | F11: =IF(D11="legendary",1000,IF(D11="secret",100,"")) | G11: 0 | H11: =IF(D11="common",0,IF(D11="rare",1,IF(D11="epic",2,IF(D11="legendary",3,4))))
A12: =LOWER(Characters!$Q4)&"-s1-common" | B12: =Characters!$Q4 | C12: S1 | D12: common | E12: =Characters!$S4-"&Characters!$Q4-"&UPPER(LEFT("common",1)) | F12: =IF(D12="legendary",1000,IF(D12="secret",100,"")) | G12: 0 | H12: =IF(D12="common",0,IF(D12="rare",1,IF(D12="epic",2,IF(D12="legendary",3,4))))
A13: =LOWER(Characters!$Q4)&"-s1-rare" | B13: =Characters!$Q4 | C13: S1 | D13: rare | E13: =Characters!$S4-"&Characters!$Q4-"&UPPER(LEFT("rare",1)) | F13: =IF(D13="legendary",1000,IF(D13="secret",100,"")) | G13: 0 | H13: =IF(D13="common",0,IF(D13="rare",1,IF(D13="epic",2,IF(D13="legendary",3,4))))
A14: =LOWER(Characters!$Q4)&"-s1-epic" | B14: =Characters!$Q4 | C14: S1 | D14: epic | E14: =Characters!$S4-"&Characters!$Q4-"&UPPER(LEFT("epic",1)) | F14: =IF(D14="legendary",1000,IF(D14="secret",100,"")) | G14: 0 | H14: =IF(D14="common",0,IF(D14="rare",1,IF(D14="epic",2,IF(D14="legendary",3,4))))
A15: =LOWER(Characters!$Q4)&"-s1-legendary" | B15: =Characters!$Q4 | C15: S1 | D15: legendary | E15: =Characters!$S4-"&Characters!$Q4-"&UPPER(LEFT("legendary",1)) | F15: =IF(D15="legendary",1000,IF(D15="secret",100,"")) | G15: 0 | H15: =IF(D15="common",0,IF(D15="rare",1,IF(D15="epic",2,IF(D15="legendary",3,4))))
A16: =LOWER(Characters!$Q4)&"-s1-secret" | B16: =Characters!$Q4 | C16: S1 | D16: secret | E16: =Characters!$S4-"&Characters!$Q4-"&UPPER(LEFT("secret",1)) | F16: =IF(D16="legendary",1000,IF(D16="secret",100,"")) | G16: 0 | H16: =IF(D16="common",0,IF(D16="rare",1,IF(D16="epic",2,IF(D16="legendary",3,4))))
A17: =LOWER(Characters!$Q5)&"-s1-common" | B17: =Characters!$Q5 | C17: S1 | D17: common | E17: =Characters!$S5-"&Characters!$Q5-"&UPPER(LEFT("common",1)) | F17: =IF(D17="legendary",1000,IF(D17="secret",100,"")) | G17: 0 | H17: =IF(D17="common",0,IF(D17="rare",1,IF(D17="epic",2,IF(D17="legendary",3,4))))
A18: =LOWER(Characters!$Q5)&"-s1-rare" | B18: =Characters!$Q5 | C18: S1 | D18: rare | E18: =Characters!$S5-"&Characters!$Q5-"&UPPER(LEFT("rare",1)) | F18: =IF(D18="legendary",1000,IF(D18="secret",100,"")) | G18: 0 | H18: =IF(D18="common",0,IF(D18="rare",1,IF(D18="epic",2,IF(D18="legendary",3,4))))
A19: =LOWER(Characters!$Q5)&"-s1-epic" | B19: =Characters!$Q5 | C19: S1 | D19: epic | E19: =Characters!$S5-"&Characters!$Q5-"&UPPER(LEFT("epic",1)) | F19: =IF(D19="legendary",1000,IF(D19="secret",100,"")) | G19: 0 | H19: =IF(D19="common",0,IF(D19="rare",1,IF(D19="epic",2,IF(D19="legendary",3,4))))
A20: =LOWER(Characters!$Q5)&"-s1-legendary" | B20: =Characters!$Q5 | C20: S1 | D20: legendary | E20: =Characters!$S5-"&Characters!$Q5-"&UPPER(LEFT("legendary",1)) | F20: =IF(D20="legendary",1000,IF(D20="secret",100,"")) | G20: 0 | H20: =IF(D20="common",0,IF(D20="rare",1,IF(D20="epic",2,IF(D20="legendary",3,4))))
A21: =LOWER(Characters!$Q5)&"-s1-secret" | B21: =Characters!$Q5 | C21: S1 | D21: secret | E21: =Characters!$S5-"&Characters!$Q5-"&UPPER(LEFT("secret",1)) | F21: =IF(D21="legendary",1000,IF(D21="secret",100,"")) | G21: 0 | H21: =IF(D21="common",0,IF(D21="rare",1,IF(D21="epic",2,IF(D21="legendary",3,4))))
A22: =LOWER(Characters!$Q6)&"-s1-common" | B22: =Characters!$Q6 | C22: S1 | D22: common | E22: =Characters!$S6-"&Characters!$Q6-"&UPPER(LEFT("common",1)) | F22: =IF(D22="legendary",1000,IF(D22="secret",100,"")) | G22: 0 | H22: =IF(D22="common",0,IF(D22="rare",1,IF(D22="epic",2,IF(D22="legendary",3,4))))
A23: =LOWER(Characters!$Q6)&"-s1-rare" | B23: =Characters!$Q6 | C23: S1 | D23: rare | E23: =Characters!$S6-"&Characters!$Q6-"&UPPER(LEFT("rare",1)) | F23: =IF(D23="legendary",1000,IF(D23="secret",100,"")) | G23: 0 | H23: =IF(D23="common",0,IF(D23="rare",1,IF(D23="epic",2,IF(D23="legendary",3,4))))
A24: =LOWER(Characters!$Q6)&"-s1-epic" | B24: =Characters!$Q6 | C24: S1 | D24: epic | E24: =Characters!$S6-"&Characters!$Q6-"&UPPER(LEFT("epic",1)) | F24: =IF(D24="legendary",1000,IF(D24="secret",100,"")) | G24: 0 | H24: =IF(D24="common",0,IF(D24="rare",1,IF(D24="epic",2,IF(D24="legendary",3,4))))
A25: =LOWER(Characters!$Q6)&"-s1-legendary" | B25: =Characters!$Q6 | C25: S1 | D25: legendary | E25: =Characters!$S6-"&Characters!$Q6-"&UPPER(LEFT("legendary",1)) | F25: =IF(D25="legendary",1000,IF(D25="secret",100,"")) | G25: 0 | H25: =IF(D25="common",0,IF(D25="rare",1,IF(D25="epic",2,IF(D25="legendary",3,4))))
A26: =LOWER(Characters!$Q6)&"-s1-secret" | B26: =Characters!$Q6 | C26: S1 | D26: secret | E26: =Characters!$S6-"&Characters!$Q6-"&UPPER(LEFT("secret",1)) | F26: =IF(D26="legendary",1000,IF(D26="secret",100,"")) | G26: 0 | H26: =IF(D26="common",0,IF(D26="rare",1,IF(D26="epic",2,IF(D26="legendary",3,4))))
A27: =LOWER(Characters!$Q7)&"-s1-common" | B27: =Characters!$Q7 | C27: S1 | D27: common | E27: =Characters!$S7-"&Characters!$Q7-"&UPPER(LEFT("common",1)) | F27: =IF(D27="legendary",1000,IF(D27="secret",100,"")) | G27: 0 | H27: =IF(D27="common",0,IF(D27="rare",1,IF(D27="epic",2,IF(D27="legendary",3,4))))
A28: =LOWER(Characters!$Q7)&"-s1-rare" | B28: =Characters!$Q7 | C28: S1 | D28: rare | E28: =Characters!$S7-"&Characters!$Q7-"&UPPER(LEFT("rare",1)) | F28: =IF(D28="legendary",1000,IF(D28="secret",100,"")) | G28: 0 | H28: =IF(D28="common",0,IF(D28="rare",1,IF(D28="epic",2,IF(D28="legendary",3,4))))
A29: =LOWER(Characters!$Q7)&"-s1-epic" | B29: =Characters!$Q7 | C29: S1 | D29: epic | E29: =Characters!$S7-"&Characters!$Q7-"&UPPER(LEFT("epic",1)) | F29: =IF(D29="legendary",1000,IF(D29="secret",100,"")) | G29: 0 | H29: =IF(D29="common",0,IF(D29="rare",1,IF(D29="epic",2,IF(D29="legendary",3,4))))
A30: =LOWER(Characters!$Q7)&"-s1-legendary" | B30: =Characters!$Q7 | C30: S1 | D30: legendary | E30: =Characters!$S7-"&Characters!$Q7-"&UPPER(LEFT("legendary",1)) | F30: =IF(D30="legendary",1000,IF(D30="secret",100,"")) | G30: 0 | H30: =IF(D30="common",0,IF(D30="rare",1,IF(D30="epic",2,IF(D30="legendary",3,4))))
A31: =LOWER(Characters!$Q7)&"-s1-secret" | B31: =Characters!$Q7 | C31: S1 | D31: secret | E31: =Characters!$S7-"&Characters!$Q7-"&UPPER(LEFT("secret",1)) | F31: =IF(D31="legendary",1000,IF(D31="secret",100,"")) | G31: 0 | H31: =IF(D31="common",0,IF(D31="rare",1,IF(D31="epic",2,IF(D31="legendary",3,4))))
A32: =LOWER(Characters!$Q8)&"-s1-common" | B32: =Characters!$Q8 | C32: S1 | D32: common | E32: =Characters!$S8-"&Characters!$Q8-"&UPPER(LEFT("common",1)) | F32: =IF(D32="legendary",1000,IF(D32="secret",100,"")) | G32: 0 | H32: =IF(D32="common",0,IF(D32="rare",1,IF(D32="epic",2,IF(D32="legendary",3,4))))
A33: =LOWER(Characters!$Q8)&"-s1-rare" | B33: =Characters!$Q8 | C33: S1 | D33: rare | E33: =Characters!$S8-"&Characters!$Q8-"&UPPER(LEFT("rare",1)) | F33: =IF(D33="legendary",1000,IF(D33="secret",100,"")) | G33: 0 | H33: =IF(D33="common",0,IF(D33="rare",1,IF(D33="epic",2,IF(D33="legendary",3,4))))
A34: =LOWER(Characters!$Q8)&"-s1-epic" | B34: =Characters!$Q8 | C34: S1 | D34: epic | E34: =Characters!$S8-"&Characters!$Q8-"&UPPER(LEFT("epic",1)) | F34: =IF(D34="legendary",1000,IF(D34="secret",100,"")) | G34: 0 | H34: =IF(D34="common",0,IF(D34="rare",1,IF(D34="epic",2,IF(D34="legendary",3,4))))
A35: =LOWER(Characters!$Q8)&"-s1-legendary" | B35: =Characters!$Q8 | C35: S1 | D35: legendary | E35: =Characters!$S8-"&Characters!$Q8-"&UPPER(LEFT("legendary",1)) | F35: =IF(D35="legendary",1000,IF(D35="secret",100,"")) | G35: 0 | H35: =IF(D35="common",0,IF(D35="rare",1,IF(D35="epic",2,IF(D35="legendary",3,4))))
A36: =LOWER(Characters!$Q8)&"-s1-secret" | B36: =Characters!$Q8 | C36: S1 | D36: secret | E36: =Characters!$S8-"&Characters!$Q8-"&UPPER(LEFT("secret",1)) | F36: =IF(D36="legendary",1000,IF(D36="secret",100,"")) | G36: 0 | H36: =IF(D36="common",0,IF(D36="rare",1,IF(D36="epic",2,IF(D36="legendary",3,4))))
A37: =LOWER(Characters!$Q9)&"-s1-common" | B37: =Characters!$Q9 | C37: S1 | D37: common | E37: =Characters!$S9-"&Characters!$Q9-"&UPPER(LEFT("common",1)) | F37: =IF(D37="legendary",1000,IF(D37="secret",100,"")) | G37: 0 | H37: =IF(D37="common",0,IF(D37="rare",1,IF(D37="epic",2,IF(D37="legendary",3,4))))
A38: =LOWER(Characters!$Q9)&"-s1-rare" | B38: =Characters!$Q9 | C38: S1 | D38: rare | E38: =Characters!$S9-"&Characters!$Q9-"&UPPER(LEFT("rare",1)) | F38: =IF(D38="legendary",1000,IF(D38="secret",100,"")) | G38: 0 | H38: =IF(D38="common",0,IF(D38="rare",1,IF(D38="epic",2,IF(D38="legendary",3,4))))
A39: =LOWER(Characters!$Q9)&"-s1-epic" | B39: =Characters!$Q9 | C39: S1 | D39: epic | E39: =Characters!$S9-"&Characters!$Q9-"&UPPER(LEFT("epic",1)) | F39: =IF(D39="legendary",1000,IF(D39="secret",100,"")) | G39: 0 | H39: =IF(D39="common",0,IF(D39="rare",1,IF(D39="epic",2,IF(D39="legendary",3,4))))
A40: =LOWER(Characters!$Q9)&"-s1-legendary" | B40: =Characters!$Q9 | C40: S1 | D40: legendary | E40: =Characters!$S9-"&Characters!$Q9-"&UPPER(LEFT("legendary",1)) | F40: =IF(D40="legendary",1000,IF(D40="secret",100,"")) | G40: 0 | H40: =IF(D40="common",0,IF(D40="rare",1,IF(D40="epic",2,IF(D40="legendary",3,4))))
...

Sheet Packs
A1: packCode | B1: name | C1: edition | D1: costTickets | E1: costGems | F1: common% | G1: rare% | H1: epic% | I1: legendary% | J1: secret% | K1: tags
A2: STANDARD | B2: Standard Pack | C2: S1 | D2: 1 | E2: 350 | F2: 50 | G2: 30 | H2: 14 | I2: 5 | J2: 1 | K2: x5 cards,Standard odds
A3: PREMIUM | B3: Premium Pack | C3: S1 | E3: 650 | F3: 33 | G3: 32 | H3: 20 | I3: 12 | J3: 3 | K3: x5 cards,Boosted odds

Sheet Références
A1: NATIONS → prefix (refCode)
A2: france | B2: FR
A3: allemagne | B3: DE
A4: angleterre | B4: GB
A5: italie | B5: IT
A6: espagne | B6: ES
A7: bresil | B7: BR
A8: japon | B8: JP
A9: argentine | B9: AR
A11: POSTES NATURELS (12) — SS = RÔLE
A12: GK/RB/LB/CB/CDM/CM/CAM/LM/RM/LW/RW/ST | B12: 12 cases FM
A13: SS | B13: RÔLE (second_striker), pas une position. Mettre dans col role.
A15: ARCHETYPES → STATS (PROFIL, pas boost OVR)
A16: Principe | B16: base OVR fixe (capée 93). Les archetypes RÉPARTISSENT le budget : montent les stats du profil, baissent d'autres. Stacker 3 archetypes = carte PLUS SPÉCIALISÉE, pas plus forte.
A17: vitesse | B17: Vitesse/Accélération/Agilité/Détente ↑ | autres ↓
A18: rugueux | B18: Tacle/Agressivité/Puissance/Positionnement ↑
A19: finition | B19: Tir/Détente/Technique/Sang-Froid ↑
A20: tete | B20: Détente/Puissance/Centre/Agressivité ↑
A21: vision | B21: Passe/Décision/Technique/Anticipation ↑
A22: creatif | B22: Dribble/Technique/Centre/Passe ↑
A23: pressing | B23: Endurance/Positionnement/Tacle/Agressivité ↑
A24: aerien | B24: Détente/AerialReach/Puissance ↑ (GK)
A25: mur | B25: Tacle/Positionnement/Puissance/Anticipation ↑
A26: box2box | B26: Endurance/Positionnement/Passe/Tacle ↑
A27: regista | B27: Passe/Décision/Technique/Anticipation ↑
... A34: sweeper | B34: RushingOut/Réflexes/Agilité/Anticipation ↑ (GK)
A36: STYLES (5, LIBRE, roue RPS)
A37: percussion | B37: BAT Sang-froid
A38: vista | B38: BAT Pressing
A39: pressing | B39: BAT Élévation
A40: elevation | B40: BAT Sang-froid
A41: sangFroid | B41: BAT Percussion
A43: RARETÉ → FRAC + SKILLS (Système B)
A44: common | B44: frac 0.78 | 0 skill slot
A45: rare | B45: frac 0.85 | 1 slot
A46: epic | B46: frac 0.91 | 2 slots
A47: legendary | B47: frac 1.00 (= base) | 3 slots
A48: secret | B48: frac 1.12 | 4 slots DONT 1 SIGNATURE (arme mythique, perso signature=oui)
A49: OVR | B49: min(99, round(base × frac + jitter ±3)). Base capée 93.
A51: MALUS HORS-POSTE (Option A, FM-style)
...
